Workbook

Sheet MATERIAS_PRIMAS
A1: APLICACAO | B1: TIPO | C1: MP | D1: DISP MIN | E1: DISP MAX | F1: CaO | G1: SiO2 | H1: MgO | I1: Mn | J1: AL2O3 | K1: P | L1: FeT | M1: S | N1: TiO2 | O1: C | P1: PPC | Q1: <10,00 | R1: >6,35 | S1: >1,00 | T1: <0,105 | U1: UMIDADE | V1: HIGRO | W1: PRECO_CIF_BU | X1: KG/T B.S. – MS1E2 | Y1: KG/T B.S. – MS3 | Z1: CONSUMO B.S. – MS1E2 (T) | AA1: CONSUMO B.S. – MS3 (T) | AB1: CONSUMO TOTAL B.U. – MS1E2 + MS3 (T) | AC1: KG/T B.S. – AF2 | AD1: KG/T B.S. – AF3 | AE1: CONSUMO B.S. – AF2 (T) | AF1: CONSUMO B.S. – AF3 (T) | AG1: CONSUMO TOTAL B.U. – AF2 + AF3 (T)
A2: MS | B2: MINERIO | C2: SF MUSA | D2: 0 | E2: =167000-E3 -> 152000 | F2: 0.04 | G2: 7.55 | H2: 0.05 | I2: 0.23 | J2: 0.88 | K2: 0.043 | L2: 62.51 | M2: 0.001 | N2: 0.001 | O2: 0.001 | P2: 1.43 | Q2: 100 | R2: 5.98 | S2: 34.67 | T2: 24.01 | U2: 8 | V2: 0 | W2: 69.78
A3: MS | B3: MINERIO | C3: SF MUSA 3ºs | D3: 0 | E3: 15000 | F3: 0.04 | G3: 7 | H3: 0.05 | I3: 1 | J3: 2.8 | K3: 0.08 | L3: 59 | M3: 0.001 | N3: 0.001 | O3: 0.001 | P3: 6 | Q3: 100 | R3: 19 | S3: 60 | T3: 10 | U3: 8 | V3: 0 | W3: 69.78
A4: MS | B4: MINERIO | C4: PF MUSA | D4: 0 | E4: 3000 | F4: 0.04 | G4: 2.5 | H4: 0.05 | I4: 1 | J4: 0.95118049 | K4: 0.07163492 | L4: 65.11214 | M4: 0.001 | N4: 0.001 | O4: 0.001 | P4: 2.786649 | Q4: 100 | R4: 0 | S4: 0.05 | T4: 90 | U4: 13 | V4: 0 | W4: 78.31
A5: MS | B5: MINERIO | C5: SF MINERITA | D5: 0 | E5: 30000 | F5: 0.04 | G5: 6.72 | H5: 0.05 | I5: 0.069 | J5: 1.059 | K5: 0.051 | L5: 63.26 | M5: 0.001 | N5: 0.001 | O5: 0.001 | P5: 1.58 | Q5: 100 | R5: 3.814 | S5: 40.78 | T5: 21.82 | U5: 6.29 | V5: 0 | W5: 71.34
A6: MS | B6: MINERIO | C6: SF V&M | D6: 0 | E6: 40000 | F6: 0.0107 | G6: 6.89795 | H6: 0.0862 | I6: 0.20465 | J6: 1.447825 | K6: 0.069725 | L6: 60.155375 | M6: 0 | N6: 0 | O6: 0 | P6: 5.0310625 | Q6: 100 | R6: 17.572237 | S6: 76.872438 | T6: 10.406075 | U6: 10.5 | V6: 0 | W6: 68.86
A7: MS | B7: MINERIO | C7: SF MSL | D7: 0 | E7: 30000 | F7: 0.09 | G7: 4.2345 | H7: 0.21209913 | I7: 1.2898333 | J7: 2.3795 | K7: 0.0565 | L7: 61.065 | M7: 0.001 | N7: 0.001 | O7: 0 | P7: 3.9125 | Q7: 100 | R7: 22.332667 | S7: 41.246167 | T7: 26.621167 | U7: 10 | V7: 0 | W7: 83.97
A8: MS | B8: MINERIO | C8: SF BEMISA | D8: 0 | E8: 66000 | F8: 1.4115 | G8: 3.6499345 | H8: 0.982 | I8: 0.13008793 | J8: 1.0724226 | K8: 0.10022709 | L8: 63.715618 | M8: 0 | N8: 0 | O8: 0 | P8: 1.1622074 | Q8: 100 | R8: 2.9221516 | S8: 18.0908 | T8: 3.6214552 | U8: 3 | V8: 0 | W8: 65.78
A9: MS | B9: MINERIO | C9: SF HERCULANO | D9: 0 | E9: 60000 | F9: 0.3405 | G9: 6.65 | H9: 0.129 | I9: 0.45 | J9: 1.75 | K9: 0.045 | L9: 61.75 | M9: 0.001 | N9: 0.001 | O9: 0.001 | P9: 2.35 | Q9: 100 | R9: 7.75 | S9: 41.5 | T9: 24 | U9: 8.5 | V9: 0 | W9: 66.189524
A10: MS | B10: MINERIO | C10: SF VALE | D10: 0 | E10: 40000 | F10: 0.0107 | G10: 7.67336 | H10: 0.0862 | I10: 0.46696 | J10: 1.20786 | K10: 0.06608 | L10: 60.9442 | M10: 0 | N10: 0 | O10: 0 | P10: 3.0585 | Q10: 100 | R10: 22.0734 | S10: 59.13018 | T10: 15.88134 | U10: 10 | V10: 1 | W10: 82.05
A11: MS | B11: MINERIO | C11: SF GSM | D11: 0 | E11: 40000 | F11: 0.056787515 | G11: 5.02106 | H11: 0.089692172 | I11: 0.10423778 | J11: 2.6462589 | K11: 0.10607889 | L11: 60.19575 | M11: 0 | N11: 0 | O11: 0 | P11: 5.5399278 | Q11: 100 | R11: 19.430981 | S11: 54.378092 | T11: 17.153952 | U11: 11.5 | V11: 1 | W11: 74.14
A12: MS | B12: MINERIO | C12: MN NOGUEIRA DUARTE | D12: 0 | E12: 0 | F12: 0.0457 | G12: 8.165 | H12: 0.068 | I12: 9.12125 | J12: 3.8714167 | K12: 0.05975 | L12: 44.01175 | M12: 1e-05 | N12: 1e-05 | O12: 1e-05 | P12: 9.5345833 | Q12: 100 | R12: 9.35475 | S12: 55.420083 | T12: 10.273833 | U12: 22.6 | V12: 1 | W12: 55.61
A13: MS | B13: RECICLADO | C13: Finos de NPO | D13: 0 | E13: 0 | F13: 0.10774109 | G13: 6.722631 | H13: 0.075143149 | I13: 0.4215736 | J13: 2.772017 | K13: 0.091477901 | L13: 58.49 | M13: 0 | N13: 0 | O13: 0.01 | P13: 6.64 | Q13: 100 | R13: 37.19 | S13: 71.03 | T13: 12.35 | U13: 6.6 | V13: 0 | W13: 34.489533
A14: MS | B14: RECICLADO | C14: Sinter Fino | D14: 0 | E14: =((PROCESSO_MS!D27*-1)+PROCESSO_MS!D2)*(1-PROCESSO_MS!D22) -> 55008.665 | F14: 10.401652 | G14: 6.4197132 | H14: 1.6131809 | I14: 0.27050016 | J14: 1.5950591 | K14: 0.084253023 | L14: 53.47013 | M14: 0 | N14: 0 | O14: 0.01 | P14: 4.2376528 | Q14: 100 | R14: 2.48 | S14: 77.73 | T14: 4.24 | U14: 0.25 | V14: 0 | W14: 61.634768
A15: MS | B15: RECICLADO | C15: Carepa | D15: 0 | E15: 50000 | F15: 1.9717451 | G15: 1.043 | H15: 0.38184314 | I15: 0.52772549 | J15: 0.37029412 | K15: 0.04372549 | L15: 70.030608 | M15: 0 | N15: 0 | O15: 0.01 | P15: 0.0054117647 | Q15: 100 | R15: 3.1442157 | S15: 31.652431 | T15: 9.8711373 | U15: 10 | V15: 0 | W15: 9.51
A16: MS | B16: RECICLADO | C16: Reciclado Industrial | D16: =E16 -> 12360.017 | E16: =0.04061*PROCESSO_MS!D2/(1-MATERIAS_PRIMAS!U16/100)-4819 -> 12360.017 | F16: 10.52656 | G16: 7.45876 | H16: 1.66968 | I16: 0.35768 | J16: 1.92094 | K16: 0.08524 | L16: 46.3429 | M16: 0 | N16: 0 | O16: 6.0082 | P16: 12.37 | Q16: 100 | R16: 13.02024 | S16: 39.01802 | T16: 15.0299 | U16: 8 | V16: 0 | W16: 61.634768
A17: MS | B17: RECICLADO | C17: Sucata tipo D | D17: 0 | E17: 0 | F17: 17.81 | G17: 5.5 | H17: 6.2 | I17: 1.29 | J17: 3.3 | K17: 0.153 | L17: 31.63 | M17: 0 | N17: 0 | O17: 3.45 | P17: 4.92 | Q17: 100 | R17: 2.97 | S17: 46.06 | T17: 8.07 | U17: 6 | V17: 0 | W17: 0.01
A18: MS | B18: RECICLADO | C18: Po de Coletor de AF | D18: =E18 -> 3835.8428 | E18: =0.01351*SUM(PROCESSO_AF!C6:D6)/(1-U18/100)+32 -> 3835.8428 | F18: 4.51355 | G18: 7.864775 | H18: 0.707825 | I18: 0.3287 | J18: 2.27895 | K18: 0.088725 | L18: 38.185453 | M18: 0 | N18: 0 | O18: 23.301525 | P18: 31.15975 | Q18: 100 | R18: 2.266275 | S18: 12.909225 | T18: 22.487225 | U18: 1 | V18: 0 | W18: 0.01
A19: MS | B19: RECICLADO | C19: Po de Sinter | D19: =E19 -> 6099.066 | E19: =0.023*SUM(PROCESSO_AF!C6:D6)-312 -> 6099.066 | F19: 18.753 | G19: 6.4315 | H19: 2.1335 | I19: 0.2435 | J19: 1.2218731 | K19: 0.1015 | L19: 40.367 | M19: 0 | N19: 0 | O19: 0.01 | P19: 7.14 | Q19: 100 | R19: 0.01 | S19: 5.1 | T19: 51 | U19: 0 | V19: 0 | W19: 0.01
A20: MS | B20: FUNDENTES | C20: Cal Fina | D20: 0 | E20: 30000 | F20: 91.83 | G20: 1.63 | H20: 1 | I20: 0.013 | J20: 0.47 | K20: 0.084 | L20: 0.164 | M20: 0 | N20: 0 | O20: 0.001 | P20: 3.58 | Q20: 100 | R20: 0.007 | S20: 12.44 | T20: 38.51 | U20: 0 | V20: 0 | W20: 108.72
A21: MS | B21: FUNDENTES | C21: Calcario | D21: 0 | E21: 60000 | F21: 54.64 | G21: 1.51 | H21: 0.35 | I21: 0.010333333 | J21: 0.4 | K21: 0.066 | L21: 0.4 | M21: 0 | N21: 0 | O21: 0.001 | P21: 42.7 | Q21: 100 | R21: 1.1 | S21: 53.29 | T21: 22.93 | U21: 4 | V21: 0 | W21: 28.245753
A22: MS | B22: FUNDENTES | C22: Dolomita | D22: =E22 -> 0 | E22: 0 | F22: 34.005 | G22: 3.555 | H22: 15.85 | I22: 0.04 | J22: 0.735 | K22: 0.015 | L22: 0.54 | M22: 0 | N22: 0 | O22: 0.001 | P22: 43.73 | Q22: 100 | R22: 1.575 | S22: 61.535 | T22: 7.125 | U22: 4 | V22: 0 | W22: 17.2925
A23: MS | B23: FUNDENTES | C23: Lama de Dolomita Calcinada | D23: 0 | E23: 1000 | F23: 42.147889 | G23: 3.7148889 | H23: 9.7734444 | I23: 0.42977778 | J23: 0.622 | K23: 0.066888889 | L23: 9.6335556 | M23: 0 | N23: 0 | O23: 0.55 | P23: 21.695556 | Q23: 100 | R23: 6.23 | S23: 23.87 | T23: 31.01 | U23: 10 | V23: 0 | W23: 17.2925
A24: MS | B24: FUNDENTES | C24: Po Desp. Dolomita | D24: 0 | E24: 0 | F24: 32 | G24: 3 | H24: 18 | I24: 0.049 | J24: 1.2 | K24: 0.0217 | L24: 0.6 | M24: 0 | N24: 0 | O24: 1e-05 | P24: 44.7 | Q24: 100 | R24: 0.79 | S24: 5 | T24: 50 | U24: 0 | V24: 0 | W24: 17.2925
A25: MS | B25: FUNDENTES | C25: Magnesiano | D25: 0 | E25: 20000 | F25: 0.36 | G25: 2.61 | H25: 44.59 | I25: 0.37 | J25: 0.57 | K25: 0.003 | L25: 2.11 | M25: 0 | N25: 0 | O25: 1e-06 | P25: 47.3 | Q25: 100 | R25: 4.65 | S25: 50.1 | T25: 11.19 | U25: 3 | V25: 0 | W25: 74.205158
A26: MS | B26: FUNDENTES | C26: Cal Fina Interna | D26: =E26 -> 389.18236 | E26: =0.001*PROCESSO_MS!$D$2 -> 389.18236 | F26: 92.632563 | G26: 1.9756563 | H26: 1.061125 | I26: 0.01209375 | J26: 0.43396875 | K26: 0.078875 | L26: 0.19759375 | M26: 0 | N26: 0 | O26: 0.001 | P26: 3.8075 | Q26: 100 | R26: 0.075875 | S26: 23.441469 | T26: 36.265406 | U26: 0 | V26: 0 | W26: =W20*75% -> 81.54
A27: MS | B27: CARGA_ENERGETICA | C27: Coque Fino | D27: 0 | E27: 7489.126 | F27: 0.34031353 | G27: 5.929 | H27: 0.098831517 | I27: 0.0046497528 | J27: 3.2709353 | K27: 0.18667425 | L27: 0.74740726 | M27: 0 | N27: 0 | O27: 80.15 | P27: 92.25 | Q27: 0 | R27: 0 | S27: 0 | T27: 0 | U27: 0 | V27: 0 | W27: 156.82
A28: MS | B28: CARGA_ENERGETICA | C28: Coque Fino Adq | D28: 0 | E28: 200000 | F28: 0.34031353 | G28: 7.252 | H28: 0.098831517 | I28: 0.0046497528 | J28: 3.2709353 | K28: 0.18667425 | L28: 0.74740726 | M28: 0 | N28: 0 | O28: 79.7 | P28: 94.5 | Q28: 0 | R28: 0 | S28: 0 | T28: 0 | U28: 0 | V28: 0 | W28: 176.83527
A29: MS | B29: CARGA_ENERGETICA | C29: Moinha | D29: 0 | E29: 499 | F29: 0.29 | G29: 1.5 | H29: 0.13 | I29: 0.01 | J29: 3.85 | K29: 0.032 | L29: 0.7 | M29: 0 | N29: 0 | O29: 80.88 | P29: 89.681 | Q29: 0 | R29: 0 | S29: 0 | T29: 0 | U29: 0 | V29: 0 | W29: 25.31
A30: MS | B30: CARGA_ENERGETICA | C30: Po de Despoeiramento Coque | D30: 0 | E30: 70 | F30: 0.29 | G30: 6.12 | H30: 0.13 | I30: 0.01 | J30: 3.85 | K30: 0.032 | L30: 0.7 | M30: 0 | N30: 0 | O30: 80.88 | P30: 88.5 | Q30: 0 | R30: 0 | S30: 0 | T30: 0 | U30: 0 | V30: 0 | W30: 25.31
A31: AF | B31: SINTER | C31: MS1E2 | D31: 0 | E31: =PROCESSO_MS!B23 -> 190628.59 | F31: 0 | G31: 0 | H31: 0 | I31: 0 | J31: 0 | K31: 0 | L31: 0 | M31: 0 | N31: 0 | O31: 0 | P31: 0 | Q31: 0 | R31: 0 | S31: 0 | T31: 0 | U31: 0 | V31: 0 | W31: 0
A32: AF | B32: SINTER | C32: MS3 | D32: 0 | E32: =PROCESSO_MS!C23 -> 143545.1 | F32: 0 | G32: 0 | H32: 0 | I32: 0 | J32: 0 | K32: 0 | L32: 0 | M32: 0 | N32: 0 | O32: 0 | P32: 0 | Q32: 0 | R32: 0 | S32: 0 | T32: 0 | U32: 0 | V32: 0 | W32: 0
A33: AF | B33: SINTER | C33: PATIO RETOMADO | D33: 0 | E33: =IF(PROCESSO_MS!D27<0,(PROCESSO_MS!D27*-1),(0)) -> 0 | F33: 10.939287 | G33: 6.1982615 | H33: 1.3482374 | I33: 0.29272801 | J33: 1.6946243 | K33: 0.089617271 | L33: 55.692336 | M33: 0 | N33: 0 | O33: 0 | P33: 0 | Q33: 0 | R33: 0 | S33: 0 | T33: 0 | U33: 0 | V33: 0 | W33: 87
A34: AF | B34: SINTER | C34: PATIO RECOMPOSTO | D34: 0 | E34: =IF(PROCESSO_MS!D27<0,(0),(PROCESSO_MS!D27)) -> 0 | F34: 0 | G34: 0 | H34: 0 | I34: 0 | J34: 0 | K34: 0 | L34: 0 | M34: 0 | N34: 0 | O34: 0 | P34: 0 | Q34: 0 | R34: 0 | S34: 0 | T34: 0 | U34: 0 | V34: 0 | W34: 0
A35: AF | B35: NPO | C35: FERRO PURO | D35: 0 | E35: 0 | F35: 0.16 | G35: 2.83 | H35: 0.182 | I35: 0.07 | J35: 3.01 | K35: 0.1023 | L35: 61.14 | M35: 0.01 | N35: 0.175 | O35: 0 | P35: 6.12 | Q35: 15.22 | R35: 0 | S35: 0 | T35: 0 | U35: 6.8 | V35: 0 | W35: 99.67
A36: AF | B36: NPO | C36: GSM BUFALOS | D36: 0 | E36: 0 | F36: 0.019 | G36: 3.1243333 | H36: 0.027 | I36: 0.062833333 | J36: 3.5426667 | K36: 0.11933333 | L36: 60.078333 | M36: 0.01 | N36: 0.19 | O36: 0 | P36: 6.74 | Q36: 17.967667 | R36: 0 | S36: 0 | T36: 0 | U36: 7.36 | V36: 0 | W36: 101.49
A37: AF | B37: NPO | C37: HERCULANO | D37: 0 | E37: 12000 | F37: 0.05 | G37: 8.1784199 | H37: 0.05 | I37: 0.28 | J37: 3.03 | K37: 0.094104131 | L37: 58.013382 | M37: 0.01 | N37: 0.04 | O37: 0 | P37: 4.95 | Q37: 19.292967 | R37: 0 | S37: 0 | T37: 0 | U37: 6.4 | V37: 0 | W37: 78.63
A38: AF | B38: NPO | C38: MSL | D38: 0 | E38: 15000 | F38: 0.09 | G38: 1.64 | H38: 0.03 | I38: 2.1 | J38: 4.13 | K38: 0.08 | L38: 58.63 | M38: 0.01 | N38: 0.08 | O38: 0 | P38: 7.19 | Q38: 18.21 | R38: 0 | S38: 0 | T38: 0 | U38: 6.3 | V38: 0 | W38: 89.08
A39: AF | B39: NPO | C39: VALE | D39: 0 | E39: 0 | F39: 0.02 | G39: 13.53 | H39: 0.03 | I39: 0.99 | J39: 0.82 | K39: 0.03 | L39: 53.89 | M39: 0.01 | N39: 0.19 | O39: 0 | P39: 2.71 | Q39: 11.3 | R39: 0 | S39: 0 | T39: 0 | U39: 8 | V39: 0 | W39: 74.945
A40: AF | B40: NPO | C40: VALLOUREC | D40: 30000 | E40: 30000 | F40: 0.16 | G40: 6.49 | H40: 0.18 | I40: 0.17 | J40: 2 | K40: 0.0754 | L40: 59.78 | M40: 0.01 | N40: 0.04 | O40: 0 | P40: 5.52 | Q40: 15.94 | R40: 0 | S40: 0 | T40: 0 | U40: 7.3 | V40: 0 | W40: 95.05
...

Sheet PERFORMANCE
A1: PARAMETRO | B1: MS1 | C1: MS2 | D1: MS3 | E1: MS1e2 | F1: GLOBAL
A2: IUT | B2: 0.66638642 | C2: 0.85172849 | D2: 0.81891801 | E2: =(B2*B4+C2*C4)/(B4+C4) -> 0.81260106 | F2: =(B2*B4+C2*C4+D2*D4)/(B4+C4+D4) -> 0.81531452
A3: PRODUTIVIDADE | B3: 95.579946 | C3: 279.44812 | D3: 277.42491 | E3: =C3+B3 -> 375.02807 | F3: =D3+C3+B3 -> 652.45298
A4: PRODUCAO | B4: =B2*B3*F14*24 -> 46867.988 | C4: =C2*C3*F14*24 -> 175140.17 | D4: =D3*D2*F14*24 -> 167174.2 | E4: =SUM(B4:C4) -> 222008.16 | F4: =SUM(B4:D4) -> 389182.36
A5: HS_PARADA | B5: 147.5 | C5: 52 | D5: 81.333333 | E5: =C5+B5 -> 199.5 | F5: =SUM(B5:D5) -> 280.83333
A6: SINTER_PATIO | B6: =B5*B3 -> 14098.042 | C6: =C5*C3 -> 14531.302 | D6: =D5*D3 -> 22563.892 | E6: =C6+B6 -> 28629.344 | F6: =SUM(B6:D6) -> 51193.237
A7: PARTICIPACAO_PATIO | F7: =F6/(F4*102%) -> 0.12896126
A8: PARTICIPACAO_DIRETO | F8: =1-F7 -> 0.87103874
A9: REND_PATIO | F9: 0.728
A10: REND_DIRETO | F10: 0.878
A11: RENDIMENTO_SINTER | F11: =(F7*F9+F8*F10) -> 0.85865581
A12: PAM_SINTER | F12: =1000/F11 -> 1164.611
A14: DIAS | F14: 30.66 | I14: 30.17
A15: PERIODO | F15: CHUVA

Sheet PROCESSO_MS
A1: PARAMETRO | B1: MS1e2 | C1: MS3 | D1: GLOBAL | E1: UNIDADE
A2: PROD_FIXA | B2: =PERFORMANCE!E4 -> 222008.16 | C2: =PERFORMANCE!D4 -> 167174.2 | D2: =SUM(B2:C2) -> 389182.36 | E2: t bsr
A3: FET_MIN | B3: 50 | C3: 50 | D3: =(B3*$B$2+C3*$C$2)/$D$2 -> 50 | E3: %
A4: MN_MIN | B4: 0 | C4: 0 | D4: =(B4*$B$2+C4*$C$2)/$D$2 -> 0 | E4: %
A5: P_MAX | B5: 1 | C5: 1 | D5: =(B5*$B$2+C5*$C$2)/$D$2 -> 1 | E5: %
A6: B2_MIN | B6: 1.7 | C6: 1.7 | D6: =(B6*$B$2+C6*$C$2)/$D$2 -> 1.7 | E6: fração
A7: B2_MAX | B7: 1.9 | C7: 1.9 | D7: =(B7*$B$2+C7*$C$2)/$D$2 -> 1.9 | E7: fração
A8: MGO_MIN | B8: 1.35 | C8: 1.35 | D8: =(B8*$B$2+C8*$C$2)/$D$2 -> 1.35 | E8: %
A9: MGO_MAX | B9: 1.65 | C9: 1.65 | D9: =(B9*$B$2+C9*$C$2)/$D$2 -> 1.65 | E9: %
A10: CAREPA_MAX_KG_T | B10: 29.6 | C10: 29.6 | D10: =(B10*$B$2+C10*$C$2)/$D$2 -> 29.6 | E10: kg/t
A11: LIM_MUSA_BEMISA | B11: 0.83 | C11: 0.83 | D11: =(B11*$B$2+C11*$C$2)/$D$2 -> 0.83 | E11: fração
A12: LIM_BEMISA | B12: 0.23 | C12: 0.23 | D12: =(B12*$B$2+C12*$C$2)/$D$2 -> 0.23 | E12: fração
A13: HIGRO_LIM_CHUVA | B13: 0 | C13: 0 | D13: 55000 | E13: t b.u
A14: HIGRO_LIM_SECA | B14: 0 | C14: 0 | D14: 990000 | E14: t b.u
A15: CAL_FINA | B15: 40 | C15: 40 | D15: =(B15*$B$2+C15*$C$2)/$D$2 -> 40 | E15: kg/t
A16: CARGA_ENERGETICA | B16: 50.66 | C16: 50.66 | D16: =(B16*$B$2+C16*$C$2)/$D$2 -> 50.66 | E16: kg/t
A17: RN_MIN | B17: 0.58 | C17: 0.58 | D17: =(B17*$B$2+C17*$C$2)/$D$2 -> 0.58 | E17: fração
A18: RN_MAX | B18: 0.99 | C18: 0.99 | D18: =(B18*$B$2+C18*$C$2)/$D$2 -> 0.99 | E18: fração
A19: FRAC_GT1_MIN | B19: 0.44 | C19: 0.43 | D19: =(B19*$B$2+C19*$C$2)/$D$2 -> 0.43570448 | E19: fração
A20: PROP_TOL | B20: 0.05 | C20: 0.05 | D20: =(B20*$B$2+C20*$C$2)/$D$2 -> 0.05 | E20: fração
A21: PERDA_FISICA | B21: 0.04 | C21: 0.04 | D21: =(B21*$B$2+C21*$C$2)/$D$2 -> 0.04 | E21: fração
A22: RENDIMENTO_SINTER | B22: =PERFORMANCE!F11 -> 0.85865581 | C22: =PERFORMANCE!F11 -> 0.85865581 | D22: =(B22*$B$2+C22*$C$2)/$D$2 -> 0.85865581 | E22: fração
A23: PRODUCAO_SINTER_AF | B23: =B2*B22 -> 190628.59 | C23: =C2*C22 -> 143545.1 | D23: =SUM(B23:C23) -> 334173.7 | E23: t bsr
A24: GERACAO_SINTER_FINO | B24: =B2-B23 -> 31379.563 | C24: =C2-C23 -> 23629.102 | D24: =SUM(B24:C24) -> 55008.665 | E24: t bsr
A25: ESTOQUE_PP_INICIAL | B25: 0 | C25: 0 | D25: 57000 | E25: t bsr
A26: ESTOQUE_PP_FINAL | B26: 0 | C26: 0 | D26: 57000 | E26: t bsr
A27: DELTA_ESTOQUE | B27: 0 | C27: 0 | D27: =D26-D25 -> 0 | E27: t bsr
A28: ESTOQUE_MAX_PATIO | B28: 0 | C28: 0 | D28: 80000 | E28: t bsr
A29: SINTER_AF_EF | B29: 0 | C29: 0 | D29: =D23-D27 -> 334173.7 | E29: t bsr
A30: CUSTO_OP_VAR_MS | B30: =5.09 -> 5.09 | C30: 5.09 | D30: =(B30*B2+C30*C2)/D2 -> 5.09 | E30: US$/t

Sheet PROCESSO_AF
A1: APLICACAO | B1: PARAMETRO | C1: AF2 | D1: AF3
A2: CARGA | B2: NPO_MIN | C2: 0 | D2: 0
A3: CARGA | B3: NPO_MAX | C3: 13.8 | D3: 16
A4: CARGA | B4: PELOTA_MIN | C4: 3 | D4: 13
A5: CARGA | B5: SINTER_MAX | C5: 100 | D5: 100
A6: GUSA | B6: PROD_TARGET | C6: 55831 | D6: 222911
A7: GUSA | B7: MN_MIN | C7: 0.35 | D7: 0.35
A8: GUSA | B8: P_MAX | C8: 0.145 | D8: 0.145
A9: GUSA | B9: COQUE_RATE | C9: 411.47717 | D9: 363.23021
A10: GUSA | B10: PCI_RATE | C10: 125.09901 | D10: 162.77113
A11: GUSA | B11: FUEL_RATE | C11: =SUM(C9:C10) -> 536.57618 | D11: =SUM(D9:D10) -> 526.00134
A12: ESCORIA | B12: SLAG_RATE_TARGET | C12: 350 | D12: 337.12 | F12: Ritmo AF3 (t/d) | G12: Slag AF3 (t/d)
A13: ESCORIA | B13: SLAG_RATE_MAX | C13: 350 | D13: =$G$13*1000/$F$13 -> 337.12375 | F13: =((5*7300+7*7600)/12) -> 7475 | G13: 2520
A14: ESCORIA | B14: FATOR_OXIDOS | C14: 0.949 | D14: 0.96
A15: ESCORIA | B15: B2_MIN | C15: 1.2 | D15: 1.2
A16: ESCORIA | B16: B2_MAX | C16: 1.21 | D16: 1.21
A17: ESCORIA | B17: B3_MIN | C17: 1.38 | D17: 1.38
A18: ESCORIA | B18: B3_MAX | C18: 1.4 | D18: 1.4
A19: ESCORIA | B19: QZ_MIN | C19: 2 | D19: 3
A20: ESCORIA | B20: QZ_MAX | C20: 5 | D20: 8
A21: GUSA | B21: CUSTO_OP_VAR_AF | C21: 69.0988 | D21: 67.511819

Sheet KPIS_MS
A1: KPI | B1: MS1E2 | C1: MS3 | D1: GLOBAL
A2: PROD_BSR
A3: FET
A4: SIO2
A5: AL2O3
A6: CAO
A7: MGO
A8: MN
A9: P
A10: RN
A11: >1MM
A12: >6.3MM
A13: <0.105MM
... A24: CARGA_ENERGETICA

Sheet KPIS_AF
A1: APLICACAO | B1: KPI | C1: AF2 | D1: AF3 | E1: GLOBAL
A2: CARGA | B2: SINTER
A3: CARGA | B3: NPO
A4: CARGA | B4: PELOTA
A5: CARGA | B5: BRIQUETE
A6: CARGA | B6: PAM_CM
A7: GUSA | B7: PROD_GUSA
A8: GUSA | B8: FET
A9: GUSA | B9: MN
A10: GUSA | B10: P
A11: GUSA | B11: SI
A12: GUSA | B12: COQUE_RATE
A13: GUSA | B13: PCI_RATE
... A23: PROCESSO | B23: CUSTO_GUSA

Sheet ALFAS_GUSA_AF
A1: ELEMENTO | B1: OXIDO_ENTRADA | C1: METAL_GUSA | D1: ALFA_REDUCAO_AF2 | E1: ALFA_REDUCAO_AF3 | F1: FATOR_MASSA
A2: Fe | B2: Fe2O3 | C2: Fe | D2: 0.99 | E2: 0.992 | F2: 0.7
A3: Si | B3: SiO2 | C3: Si | D3: 0.045 | E3: 0.073 | F3: 0.467
A4: Mn | B4: MnO | C4: Mn | D4: 0.68 | E4: 0.74 | F4: 0.774
A5: P | B5: P2O5 | C5: P | D5: 0.9 | E5: 0.9 | F5: 0.436
A6: Al | B6: Al2O3 | C6: — | D6: 0 | E6: 0 | F6: 0
A7: Ca | B7: CaO | C7: — | D7: 0 | E7: 0 | F7: 0
A8: Mg | B8: MgO | C8: — | D8: 0 | E8: 0 | F8: 0

Sheet CALIBRACAO
A1: PARAMETRO | B1: MS1e2 | C1: MS3 | D1: GLOBAL | E1: UNIDADE
A2: PENAL_FINOS_FET | D2: -1.5 | E2: pontos
A3: PENAL_FINOS_SIO2 | D3: 2 | E3: pontos
A4: PENAL_FINOS_CAO | D4: 0 | E4: pontos
A5: PENAL_FINOS_MGO | D5: 0 | E5: pontos
A6: PENAL_FINOS_AL2O3 | D6: 0 | E6: pontos
A7: PENAL_FINOS_MN | D7: 0 | E7: pontos
A8: PENAL_FINOS_P | D8: 0 | E8: pontos
A9: PENAL_PPC | D9: 0.5 | E9: pontos
